Workbook
Name Slicer_DATACENTER_STAGE: #N/A
Name Slicer_DATACENTER_STAGE1: #N/A
Name Slicer_state_code7: #N/A

Sheet US 30d Comparison
A1: DATA_CENTER_STAGE | B1: q_current | C1: s_current_power_capacity_mw | D1: s_current_square_footage | E1: q_30d_ago | F1: s_30d_ago_power_capacity_mw | G1: s_30d_ago_square_footage | H1: q_delta_30d | I1: s_delta_30d_power_capacity_mw | J1: s_delta_30d_square_footage | K1: updated_at
A2: Active | B2: 2050 | C2: 50265.115 | D2: 306666979 | E2: 2026 | F2: 49052.965 | G2: 303768469 | H2: 24 | I2: 1212.15 | J2: 2898510 | K2: 46233
A3: Announcement | B3: 3905 | C3: 357584.73 | D3: 700591051 | E3: 3631 | F3: 316114.57 | G3: 655804736 | H3: 274 | I3: 41470.16 | J3: 44786315 | K3: 46233
A4: Cancelled | B4: 7 | C4: 391 | D4: 530800 | E4: 19 | F4: 1024.96 | G4: 3470800 | H4: -12 | I4: -633.96 | J4: -2940000 | K4: 46233
A5: Construction | B5: 807 | C5: 68103.12 | D5: 218578023 | E5: 766 | F5: 62649.99 | G5: 205722196 | H5: 41 | I5: 5453.13 | J5: 12855827 | K5: 46233
A6: Delayed | B6: 92 | C6: 8901.64 | D6: 19160437 | E6: 84 | F6: 7180.64 | G6: 18915437 | H6: 8 | I6: 1721 | J6: 245000 | K6: 46233
A7: Land Bank | B7: 60 | C7: 2379.52 | D7: 4050000 | E7: 54 | F7: 2379.52 | G7: 4050000 | H7: 6 | I7: 0 | J7: 0 | K7: 46233
A8: Not Approved/Withdrawn | B8: 630 | C8: 33493.04 | D8: 126567351 | E8: 552 | F8: 29942.05 | G8: 116738087 | H8: 78 | I8: 3550.99 | J8: 9829264 | K8: 46233

Sheet US Data Centers Dataset
A1: ATERIO_DATACENTER_UNIQUE_ID | B1: DATA_CENTER_BUILDING_NAME | C1: DATA_CENTER_SCATTER_PLOT_NAME | D1: PROVIDER_NAME | E1: DATACENTER_STAGE | F1: STATE_CODE | G1: STATE_NAME | H1: TOT_FACILITY_SPACE_SQFT | I1: TOT_DATACENTER_SPACE_SQFT | J1: TOT_POWER_MW | K1: RECORD_UPDATED_DATE | L1: UPDATED_AT
A2: 1f0a736d-3fa7-4fb1-9237-a287e7429e85 | B2: Prineville Data Center Building 2 | D2: Apple Inc. | E2: Active | F2: OR | G2: Oregon | H2: 300000 | I2: 300000 | J2: 29.703 | K2: 45535 | L2: 2026-07-31
A3: 84a56dcf-7a7e-4e43-8d56-e6263200220e | B3: Prineville Data Center Building 1 | D3: Apple Inc. | E3: Active | F3: OR | G3: Oregon | H3: 300000 | I3: 300000 | J3: 29.703 | K3: 45535 | L3: 2026-07-31
A4: 57014f52-9864-40ee-8050-a1b938138fa7 | B4: Prineville Data Center Building 3 | D4: Apple Inc. | E4: Active | F4: OR | G4: Oregon | H4: 270000 | I4: 270000 | J4: 29.213 | K4: 45535 | L4: 2026-07-31
A5: 0426f94e-6b7f-49de-adff-f04211eba271 | B5: Reno Data Center Building 1 | D5: Apple Inc. | E5: Active | F5: NV | G5: Nevada | H5: 450000 | I5: 450000 | J5: 54.562 | K5: 45535 | L5: 2026-07-31
A6: 67fd4c73-e93a-4c46-976b-cf671bd608a3 | B6: Reno Data Center Building 2 | D6: Apple Inc. | E6: Active | F6: NV | G6: Nevada | H6: 420000 | I6: 420000 | J6: 45.542 | K6: 45535 | L6: 2026-07-31
A7: 176c4ae3-2d4d-4e3d-9543-4e83564b6cf1 | B7: Reno Data Center Building 3 | D7: Apple Inc. | E7: Active | F7: NV | G7: Nevada | H7: 420000 | I7: 420000 | J7: 45.542 | K7: 45535 | L7: 2026-07-31
A8: d6eaaa00-82b5-11f0-884c-a193525c71ad | B8: Thornton Labs - Butte | D8: Company Not Disclosed | E8: Active | F8: MT | G8: Montana | K8: 45900 | L8: 2026-07-31
A9: cbeb1340-c641-11f0-8416-4dd1bc094c6c | B9: Atlas Power Butte Data Center | D9: Company Not Disclosed | E9: Active | F9: MT | G9: Montana | J9: 75 | K9: 45991 | L9: 2026-07-31
A10: 404bd811-f564-4444-b14d-f9b57bfe18df | B10: Mesa Data Center Building 1 | C10: Mesa Data Center Building 1 Mesa, Apple Campus Apple Inc. | D10: Apple Inc. | E10: Active | F10: AZ | G10: Arizona | H10: 1332000 | I10: 1332000 | J10: 85.294 | K10: 45535 | L10: 2026-07-31
A11: 00371327-8827-4ad4-8197-b3b4fa7fe7c6 | B11: Waukee IA Data Center Building 1 | D11: Apple Inc. | E11: Active | F11: IA | G11: Iowa | H11: 290000 | I11: 290000 | J11: 29.871 | K11: 45535 | L11: 2026-07-31
A12: d4e0fe10-5ec1-11f1-9ac0-c161a6bf6c99 | B12: 1831 Chesnut Data Center | D12: Company Not Disclosed | E12: Active | F12: MO | G12: Missouri | I12: 53000 | J12: 4.7324 | K12: 46203 | L12: 2026-07-31
A13: ed291889-2684-4ed4-8070-2cdacf25cf3d | B13: Chicago Data Center | D13: IT Solutions Group | E13: Active | F13: IL | G13: Illinois | I13: 120000 | J13: 8.62 | K13: 45535 | L13: 2026-07-31
A14: 4cfaa9b0-7a0f-11f1-b634-bd9fd4e3b265 | B14: i74 Wired business campus | D14: Company Not Disclosed | E14: Active | F14: OH | G14: Ohio | I14: 65000 | J14: 2 | K14: 46234 | L14: 2026-07-31
A15: 50bc18e0-55fc-11f1-8fed-dd9b759592d6 | B15: Strategic Datasphere Data Center | D15: Company Not Disclosed | E15: Active | F15: GA | G15: Georgia | I15: 165000 | J15: 5.4 | K15: 46173 | L15: 2026-07-31
A16: 020947e0-76ef-11f1-882c-4deedad4e203 | B16: Georgia Technology Center | D16: Company Not Disclosed | E16: Active | F16: GA | G16: Georgia | J16: 4.8 | K16: 46234 | L16: 2026-07-31
A17: b2f93a27-5612-43b9-826e-af1ef0e6b788 | B17: Statesboro Edge Data Center | D17: EdgePresence | E17: Active | F17: GA | G17: Georgia | H17: 360 | I17: 360 | J17: 0.1 | K17: 45535 | L17: 2026-07-31
A18: f61feb50-da3e-4797-b538-ef6337578bbf | B18: JAX2 Edge Data Center | D18: EdgePresence | E18: Active | F18: FL | G18: Florida | H18: 160 | I18: 160 | J18: 0.52375 | K18: 45535 | L18: 2026-07-31
A19: e8e1dddc-94b9-4a49-973b-b196d3edd098 | B19: Orlando Data Center | D19: IT Solutions Group | E19: Active | F19: FL | G19: Florida | I19: 130000 | J19: 10.1215 | K19: 45535 | L19: 2026-07-31
A20: 34d5dde0-cb47-4230-95a3-e009a989e5e9 | B20: Maiden Data Center Building 3 | D20: Apple Inc. | E20: Active | F20: NC | G20: North Carolina | H20: 180000 | I20: 180000 | J20: 13.9395 | K20: 45535 | L20: 2026-07-31
A21: 6c9bee4f-2d88-4f75-917c-ac75e2122009 | B21: Maiden Data Center Building 1 | D21: Apple Inc. | E21: Active | F21: NC | G21: North Carolina | H21: 420000 | I21: 420000 | J21: 46.49 | K21: 45535 | L21: 2026-07-31
A22: 826fd604-fd83-47db-a472-a793c7d372e7 | B22: Maiden Data Center Building 4 | D22: Apple Inc. | E22: Active | F22: NC | G22: North Carolina | H22: 220000 | I22: 220000 | J22: 21.933 | K22: 45535 | L22: 2026-07-31
A23: bfa07a33-552a-4dda-a5cf-c72bf0e01b7f | B23: Maiden Data Center Building 2 | D23: Apple Inc. | E23: Active | F23: NC | G23: North Carolina | H23: 200000 | I23: 200000 | J23: 17.236 | K23: 45535 | L23: 2026-07-31
A24: aa8d6670-34d4-11f0-a9e1-c9350c8c3578 | B24: Albion Data Center | D24: Company Not Disclosed | E24: Active | F24: NY | G24: New York | H24: 130000 | I24: 130000 | J24: 1 | K24: 45808 | L24: 2026-07-31
A25: 3c85e73a-2005-4de0-995b-511fb6c131b0 | B25: PTP Data Center 1 | D25: Company Not Disclosed | E25: Active | F25: VA | G25: Virginia | H25: 250000 | I25: 250000 | J25: 32.5 | K25: 45716 | L25: 2026-07-31
A26: 6a6a7eb9-2758-4fcd-aa73-845eb8f32664 | B26: PTP Data Center 2 | D26: Company Not Disclosed | E26: Active | F26: VA | G26: Virginia | H26: 250000 | I26: 250000 | J26: 32.5 | K26: 45716 | L26: 2026-07-31
A27: ea5ddd62-abb0-493e-98b5-c8b28d9763ad | B27: Asburn Data Center | D27: Atlantic.net | E27: Active | F27: VA | G27: Virginia | J27: 2 | K27: 45535 | L27: 2026-07-31
A28: 27594a60-794a-11f1-bcaf-0fe1f28909ae | B28: Roble Road Data Center | D28: Company Not Disclosed | E28: Active | F28: PA | G28: Pennsylvania | I28: 46800 | J28: 40 | K28: 46234 | L28: 2026-07-31
A29: 8c5ae027-536d-44f4-97fe-aeb2890013e0 | B29: Union Station Data Center | D29: Iron Rails Data Centers | E29: Active | F29: NY | G29: New York | I29: 97000 | J29: 4 | K29: 45535 | L29: 2026-07-31
A30: b0cedd74-da2d-40a7-bf0e-8ca9bf0b0307 | B30: 701 River Street Data Center | D30: Iron Rails Data Centers | E30: Active | F30: NY | G30: New York | K30: 45535 | L30: 2026-07-31
A31: b8942abb-9203-4445-a98b-99f81540c911 | B31: Seattle South Hill Campus | D31: Centeris | E31: Active | F31: WA | G31: Washington | H31: 150000 | I31: 150000 | J31: 40 | K31: 45535 | L31: 2026-07-31
A32: e5796f90-851e-11f1-a8ec-c382bf3e166b | B32: Kubach Rd Data Center | D32: NorthPoint Development | E32: Active | F32: PA | G32: Pennsylvania | I32: 124190 | J32: 13.2 | K32: 46234 | L32: 2026-07-31
A33: cc811930-6367-11f1-a926-fdddf37ad9ea | B33: Bitdeer Data Center Phase 2A | D33: Bitdeer | E33: Active | F33: OH | G33: Ohio | J33: 74 | K33: 46203 | L33: 2026-07-31
A34: 788dfa44-c732-4585-ba92-208143d5d8e2 | B34: Bitdeer Data Center Phase 1 | D34: Bitdeer | E34: Active | F34: OH | G34: Ohio | J34: 47 | K34: 45688 | L34: 2026-07-31
A35: b59a195f-876d-48ed-b2c7-d3d61ccf43f3 | B35: Data Center 5 | D35: Global[X]Digital | E35: Active | F35: OK | G35: Oklahoma | J35: 53 | K35: 46234 | L35: 2026-07-31
A36: ae23081e-ffff-476f-9b1d-badaadbfb759 | B36: Data Center 1 | D36: Global[X]Digital | E36: Active | F36: OK | G36: Oklahoma | J36: 53 | K36: 46234 | L36: 2026-07-31
A37: 705a882e-e4ff-4652-9cad-76ad1cb42c8f | B37: Data Center 4 | D37: Global[X]Digital | E37: Active | F37: OK | G37: Oklahoma | J37: 53 | K37: 46234 | L37: 2026-07-31
A38: 788fa154-761d-408e-b6c7-3416284929d0 | B38: Data Center 3 | D38: Global[X]Digital | E38: Active | F38: OK | G38: Oklahoma | J38: 53 | K38: 46234 | L38: 2026-07-31
A39: 08031536-2d56-4621-ae8b-3f6b75e0decb | B39: Data Center 2 | D39: Global[X]Digital | E39: Active | F39: OK | G39: Oklahoma | J39: 53 | K39: 46234 | L39: 2026-07-31
A40: 967d3e81-e6e1-44ac-93d0-710ff23d44af | B40: Data Center 6 | D40: Global[X]Digital | E40: Active | F40: OK | G40: Oklahoma | J40: 53 | K40: 46234 | L40: 2026-07-31
...

Sheet Data - Main KPIs
A1: 0. Maximum Updated Date
A3: 0.0 Updated Date Label (From Pipeline job date)
A4: Row Labels
A5: 2026-07-31
A7: 0.1 General (Recorded Date)
A8: LATEST_DATE | B8: LATEST INDEX
A9: 46234 | B9: 24
A11: 0.2 By Stage
A12: Row Labels | B12: LATEST_DATE | C12: LATEST INDEX | D12: INDEX STAGE | E12: FINAL ROW
A13: Active | B13: 46234 | C13: 22 | D13: 1 | E13: =C13-1 -> 21
A14: Announcement | B14: 46234 | C14: 24 | D14: 2 | E14: =E13+1+C14 -> 46
A15: Cancelled | B15: 46112 | C15: 6 | D15: 3 | E15: =E14+1+C15 -> 53
A16: Construction | B16: 46234 | C16: 24 | D16: 4 | E16: =E15+1+C16 -> 78
A17: Delayed | B17: 45961 | C17: 12 | D17: 5 | E17: =E16+1+C17 -> 91
A18: Not Approved/Withdrawn | B18: 46234 | C18: 23 | D18: 6 | E18: =E17+1+C18 -> 115
A22: Row Labels | B22: # Facilities
A23: Active | B23: 2050
A24: Announcement | B24: 3905
A25: Cancelled | B25: 7
A26: Construction | B26: 807
A27: Delayed | B27: 92
A28: Not Approved/Withdrawn | B28: 630
A30: Row Labels | B30: # Facilities
A31: Active | B31: 50265.133
A32: Announcement | B32: 357584.84
A33: Cancelled | B33: 390.9975
A34: Construction | B34: 68103.116
A35: Delayed | B35: 8901.6833
A36: Not Approved/Withdrawn | B36: 33493.113
A38: Row Labels | B38: # Facilities
A39: Active | B39: 306666979
A40: Announcement | B40: 700591051
A41: Cancelled | B41: 530800
A42: Construction | B42: 218578023
A43: Delayed | B43: 19160437
A44: Not Approved/Withdrawn | B44: 126567351
A46: 1. Main KPIs
A48: DATACENTER_STAGE | B48: (All)
A50: Row Labels | B50: TOTAL | C50: TOTAL ACCUM | D50: SUM POWER MWH | E50: SUM POWER MWH ACCUM | F50: AVG POWER MWH | G50: AVG POWER MWH ACCUM | H50: SUM SPACE SQFT | I50: SUM SPACE SQFT ACCUM | J50: AVG SPACE SQFT | K50: AVG SPACE SQFT ACCUM
A51: 45535 | B51: 1751 | C51: 1751 | D51: 41219.709 | E51: 41219.709 | F51: 24.801269 | G51: 24.801269 | H51: 275522711 | I51: 275522711 | J51: 168001.65 | K51: 168001.65
...

Sheet Data - DC by Project Stage
A1: 1. Facilities By US State
A2: DATACENTER_STAGE | B2: Active
A4: STATE_NAME | B4: # Facilities
A5: Virginia | B5: 334
A6: Texas | B6: 229
A7: California | B7: 167
A8: Ohio | B8: 113
A9: Oregon | B9: 100
A10: Arizona | B10: 85
A11: Illinois | B11: 79
A12: Washington | B12: 70
A13: Georgia | B13: 68
A14: Iowa | B14: 63
A61: 2. Facilities By Data Center Provider
A62: DATACENTER_STAGE | B62: Active
A64: PROVIDER_NAME | B64: TOTAL
A65: Amazon AWS | B65: 217
A66: Microsoft | B66: 122
A67: Digital Realty | B67: 107
A68: Facebook | B68: 104
A69: Lumen | B69: 97
A70: Google | B70: 86
A71: Equinix | B71: 74
A72: Cogent Communications | B72: 72
A73: QTS Data Centers | B73: 62
A74: DataBank | B74: 60
A82: 3. Power Comsumption By US State
A83: DATACENTER_STAGE | B83: Active
A85: STATE_NAME | B85: Total Power Consumption (MWh)
A86: Virginia | B86: 11745.472
A87: Texas | B87: 5952.2695
A88: Oregon | B88: 3934.1564
A89: Ohio | B89: 3777.4462
A90: Arizona | B90: 2941.423
A91: Georgia | B91: 2251.714
A92: Iowa | B92: 2062.4316
A93: Illinois | B93: 1751.3629
A94: California | B94: 1713.5105
A95: Tennessee | B95: 1340.4882
A101: 4. Power Comsumption By Data Center Provider
...

Sheet Data - ISO vs Data Centers
A4: BAL_AUTH_NAME | B4: BAL_AUTH_ABBR | C4: ENERGY DEMAND ISO | D4: DATA CENTERS POWER CAPACITY | E4: DATA CENTER ENERGY COVERAGE
A5: California Independent System Operator | B5: CISO | C5: 32929.167 | D5: 2369.1729 | E5: 0.071947551
A6: Electric Reliability Council of Texas | B6: ERCO | C6: 70928.542 | D6: 4639.3784 | E6: 0.065409189
A7: Midcontinent Independent System Operator | B7: MISO | C7: 88382.667 | D7: 4700.7741 | E7: 0.053186607
A8: New York Independent System Operator | B8: NYIS | C8: 16594.333 | D8: 287.3527 | E8: 0.017316315
A9: PJM Interconnection | B9: PJM | C9: 107546.92 | D9: 18140.567 | E9: 0.16867584
A10: Southwest Power Pool | B10: SWPP | C10: 24419.958 | D10: 1670.0983 | E10: 0.06839071
A11: ISO New England | B11: ISNE | C11: 13149.042 | D11: 227.8655 | E11: 0.017329438
A16: BAL_AUTH_ABBR | B16: Q_SUBREGION_CODE | D16: CISO
A17: MISO | B17: 5 | D17: ERCO
A18: PJM | B18: 19 | D18: SPP
A19: CISO | B19: 3 | D19: MISO
A20: ERCO | B20: 7 | D20: PJM
A21: ISNE | B21: 8 | D21: NYIS
A22: NYIS | B22: 7 | D22: ISNE
A23: SWPP | B23: 9
A24: Grand Total | B24: 58
A26: BAL_AUTH_ABBR | B26: CISO
A28: SUBREGION CODE | B28: SUBREGION NAME | C28: TOTAL DATA CENTERS | D28: ISO/RTO ENERGY DEMAND | E28: DATA CENTER POWER CAPACITY | F28: DATA CENTER ENERGY COVERAGE
A29: PGAE | B29: Pacific Gas and Electric | C29: 106 | D29: 13109.75 | E29: 1295.9584 | F29: 0.098854543
A30: SCE | B30: Southern California Edison - CISO | C30: 66 | D30: 16830.5 | E30: 1046.4699 | F30: 0.062176997
A31: SDGE | B31: San Diego Gas and Electric - CISO | C31: 10 | D31: 2988.9167 | E31: 26.7446 | F31: 0.0089479243
A32: Grand Total | C32: 182 | D32: 32929.167 | E32: 2369.1729 | F32: 0.071947551
A34: BAL_AUTH_ABBR | B34: ERCO
A36: SUBREGION CODE | B36: SUBREGION NAME | C36: TOTAL DATA CENTERS | D36: ISO/RTO ENERGY DEMAND | E36: DATA CENTER POWER CAPACITY | F36: DATA CENTER ENERGY COVERAGE
A37: COAS | B37: ERCO - Coast | C37: 28 | D37: 18370.708 | E37: 438.0347 | F37: 0.023844192
A38: EAST | B38: ERCO - East | C38: 2 | D38: 2397.6667 | E38: 8.33045 | F38: 0.0034743987
A39: FWES | B39: ERCO - Far West | C39: 7 | D39: 7811.3333 | E39: 374.9927 | F39: 0.048006235
A40: NCEN | B40: ERCO - North Central | C40: 101 | D40: 22414.5 | E40: 2128.0661 | F40: 0.094941493
A41: SCEN | B41: ERCO - South Central | C41: 54 | D41: 11986.875 | E41: 1477.3542 | F41: 0.12324765
A42: SOUT | B42: ERCO - South | C42: 8 | D42: 5743.9583 | E42: 108.6002 | F42: 0.018906857
A43: NRTH | B43: ERCO - North | C43: 3 | D43: 2203.5 | E43: 104 | F43: 0.04719764
A44: Grand Total | C44: 203 | D44: 70928.542 | E44: 4639.3784 | F44: 0.065409189
A46: BAL_AUTH_ABBR | B46: SWPP
A48: SUBREGION CODE | B48: SUBREGION NAME | C48: TOTAL DATA CENTERS | D48: ISO/RTO ENERGY DEMAND | E48: DATA CENTER POWER CAPACITY | F48: DATA CENTER ENERGY COVERAGE
A49: GRDA | B49: Grand River Dam Authority - SWPP | C49: 11 | D49: 1443.25 | E49: 507.605 | F49: 0.35170968
A50: INDN | B50: Independence Power - SWPP | C50: 8 | D50: 172.04167 | E50: 62.64575 | F50: 0.36413127
A51: LES | B51: Lincoln Electric System - SWPP | C51: 3 | D51: 681.79167 | E51: 97 | F51: 0.1422722
A52: MPS | B52: KCP&L Greater Missouri Operations - SWPP | C52: 2 | D52: 1457.75 | E52: 4.4621 | F52: 0.0030609501
A53: OKGE | B53: Oklahoma Gas and Electric Co. - SWPP | C53: 11 | D53: 6403.5417 | E53: 33.16225 | F53: 0.0051787357
...

Sheet US Overview Dashboard
B7: KPIs | AA7: US Data Center developments, August 2026 | AT7: Data Centers Facilities across the US | BL7: US States Overview | CF7: Data Centers across ISOs/RTOs
B9: Main indicators about US Data Centers | AA9: ` | AT9: Distribution of the Data Center Facilities across the US based on the latest snapshot. | BL9: Top 10 US States based on their Data Center's inventory, facility size and energy consumption. | CF9: Data Center Power Distribution by ISO/RTO, Energy and Coverage
G11: ='Data - Main KPIs'!$C$223 -> 3905 | I11: Facilities | N11: ='Data - Main KPIs'!$D$223 -> 357584.84 | P11: GW | U11: ='Data - Main KPIs'!$F$223 -> 700591051 | W11: M SqFt
I12: ='Data - Main KPIs'!$D$462 -> 0.075461305 | P12: ='Data - Main KPIs'!$E$462 -> 0.13118712 | W12: ='Data - Main KPIs'!$F$462 -> 0.068292149
I13: vs previous 30 days | P13: vs previous 30 days | W13: vs previous 30 days
G16: ='Data - Main KPIs'!$C$227 -> 630 | I16: Facilities | N16: ='Data - Main KPIs'!$D$227 -> 33493.113 | P16: GW | U16: ='Data - Main KPIs'!$F$227 -> 126567351 | W16: M SqFt
G20: ='Data - Main KPIs'!$C$225 -> 807 | I20: Facilities | N20: ='Data - Main KPIs'!$D$225 -> 68103.116 | P20: GW | U20: ='Data - Main KPIs'!$F$225 -> 218578023 | W20: M SqFt
I21: ='Data - Main KPIs'!$D$464 -> 0.053524804 | P21: ='Data - Main KPIs'!$E$464 -> 0.087041195 | W21: ='Data - Main KPIs'!$F$464 -> 0.062491201
I22: vs previous 30 days | P22: vs previous 30 days | W22: vs previous 30 days
G25: ='Data - Main KPIs'!$C$226 -> 92 | I25: Facilities | N25: ='Data - Main KPIs'!$D$226 -> 8901.6833 | P25: GW | U25: ='Data - Main KPIs'!$F$226 -> 19160437 | W25: M SqFt
G29: ='Data - Main KPIs'!$C$224 -> 7 | I29: Facilities | N29: ='Data - Main KPIs'!$D$224 -> 390.9975 | P29: GW | U29: ='Data - Main KPIs'!$F$224 -> 530800 | W29: M SqFt
G33: ='Data - Main KPIs'!$C$222 -> 2050 | I33: Facilities | N33: ='Data - Main KPIs'!$D$222 -> 50265.133 | P33: GW | U33: ='Data - Main KPIs'!$F$222 -> 306666979 | W33: M SqFt
I34: ='Data - Main KPIs'!$D$461 -> 0.011846002 | P34: ='Data - Main KPIs'!$E$461 -> 0.024711044 | W34: ='Data - Main KPIs'!$F$461 -> 0.0095418396
I35: vs previous 30 days | P35: vs previous 30 days | W35: vs previous 30 days
B37: ="Latest Update: 2026-08-01" -> Latest Update: 2026-08-01
B39: Evolution of Data Centers Facilities
B41: What is the influence in the latest from new data centers projects announced and under construction
CF57: Data Centers across ISOs/RTOs Subregions (Load Zones)
CF58: Data Center Power Distribution by ISO/RTO Load Zones, Energy and Coverage
CF64: SUBREGION CODE | CG64: SUBREGION NAME | CH64: TOTAL DATA CENTERS | CI64: ISO/RTO ENERGY DEMAND | CJ64: DATA CENTER POWER CAPACITY | CK64: DATA CENTER ENERGY COVERAGE | CN64: SUBREGION CODE | CO64: SUBREGION NAME | CP64: TOTAL DATA CENTERS | CQ64: ISO/RTO ENERGY DEMAND | CR64: DATA CENTER POWER CAPACITY | CS64: DATA CENTER ENERGY COVERAGE
CF65: ='Data - ISO vs Data Centers'!A29 -> PGAE | CG65: ='Data - ISO vs Data Centers'!B29 -> Pacific Gas and Electric | CH65: ='Data - ISO vs Data Centers'!C29 -> 106 | CI65: ='Data - ISO vs Data Centers'!D29 -> 13109.75 | CJ65: ='Data - ISO vs Data Centers'!E29 -> 1295.9584 | CK65: ='Data - ISO vs Data Centers'!F29 -> 0.098854543 | CN65: ='Data - ISO vs Data Centers'!A40 -> NCEN | CO65: ='Data - ISO vs Data Centers'!B40 -> ERCO - North Central | CP65: ='Data - ISO vs Data Centers'!C40 -> 101 | CQ65: ='Data - ISO vs Data Centers'!D40 -> 22414.5 | CR65: ='Data - ISO vs Data Centers'!E40 -> 2128.0661 | CS65: ='Data - ISO vs Data Centers'!F40 -> 0.094941493
B66: Evolution of U.S. Data Center Development Momentum | CF66: ='Data - ISO vs Data Centers'!A30 -> SCE | CG66: ='Data - ISO vs Data Centers'!B30 -> Southern California Edison - CISO | CH66: ='Data - ISO vs Data Centers'!C30 -> 66 | CI66: ='Data - ISO vs Data Centers'!D30 -> 16830.5 | CJ66: ='Data - ISO vs Data Centers'!E30 -> 1046.4699 | CK66: ='Data - ISO vs Data Centers'!F30 -> 0.062176997 | CN66: ='Data - ISO vs Data Centers'!A41 -> SCEN | CO66: ='Data - ISO vs Data Centers'!B41 -> ERCO - South Central | CP66: ='Data - ISO vs Data Centers'!C41 -> 54 | CQ66: ='Data - ISO vs Data Centers'!D41 -> 11986.875 | CR66: ='Data - ISO vs Data Centers'!E41 -> 1477.3542 | CS66: ='Data - ISO vs Data Centers'!F41 -> 0.12324765
CF67: ='Data - ISO vs Data Centers'!A31 -> SDGE | CG67: ='Data - ISO vs Data Centers'!B31 -> San Diego Gas and Electric - CISO | CH67: ='Data - ISO vs Data Centers'!C31 -> 10 | CI67: ='Data - ISO vs Data Centers'!D31 -> 2988.9167 | CJ67: ='Data - ISO vs Data Centers'!E31 -> 26.7446 | CK67: ='Data - ISO vs Data Centers'!F31 -> 0.0089479243 | CN67: ='Data - ISO vs Data Centers'!A37 -> COAS | CO67: ='Data - ISO vs Data Centers'!B37 -> ERCO - Coast | CP67: ='Data - ISO vs Data Centers'!C37 -> 28 | CQ67: ='Data - ISO vs Data Centers'!D37 -> 18370.708 | CR67: ='Data - ISO vs Data Centers'!E37 -> 438.0347 | CS67: ='Data - ISO vs Data Centers'!F37 -> 0.023844192
B68: Monthly trends in constructions and announcements activity by facilities and total power capacity since 2021 | CH68: =SUM(CH65:CH67) -> 182 | CI68: =SUM(CI65:CI67) -> 32929.167 | CJ68: =SUM(CJ65:CJ67) -> 2369.1729 | CK68: =CJ68/CI68 -> 0.071947551 | CN68: ='Data - ISO vs Data Centers'!A43 -> NRTH | CO68: ='Data - ISO vs Data Centers'!B43 -> ERCO - North | CP68: ='Data - ISO vs Data Centers'!C43 -> 3 | CQ68: ='Data - ISO vs Data Centers'!D43 -> 2203.5 | CR68: ='Data - ISO vs Data Centers'!E43 -> 104 | CS68: ='Data - ISO vs Data Centers'!F43 -> 0.04719764
CN69: ='Data - ISO vs Data Centers'!A42 -> SOUT | CO69: ='Data - ISO vs Data Centers'!B42 -> ERCO - South | CP69: ='Data - ISO vs Data Centers'!C42 -> 8 | CQ69: ='Data - ISO vs Data Centers'!D42 -> 5743.9583 | CR69: ='Data - ISO vs Data Centers'!E42 -> 108.6002 | CS69: ='Data - ISO vs Data Centers'!F42 -> 0.018906857
CN70: ='Data - ISO vs Data Centers'!A38 -> EAST | CO70: ='Data - ISO vs Data Centers'!B38 -> ERCO - East | CP70: ='Data - ISO vs Data Centers'!C38 -> 2 | CQ70: ='Data - ISO vs Data Centers'!D38 -> 2397.6667 | CR70: ='Data - ISO vs Data Centers'!E38 -> 8.33045 | CS70: ='Data - ISO vs Data Centers'!F38 -> 0.0034743987
CN71: ='Data - ISO vs Data Centers'!A39 -> FWES | CO71: ='Data - ISO vs Data Centers'!B39 -> ERCO - Far West | CP71: ='Data - ISO vs Data Centers'!C39 -> 7 | CQ71: ='Data - ISO vs Data Centers'!D39 -> 7811.3333 | CR71: ='Data - ISO vs Data Centers'!E39 -> 374.9927 | CS71: ='Data - ISO vs Data Centers'!F39 -> 0.048006235
CP72: =SUM(CP65:CP71) -> 203 | CQ72: =SUM(CQ65:CQ71) -> 70928.542 | CR72: =SUM(CR65:CR71) -> 4639.3784 | CS72: =CR72/CQ72 -> 0.065409189
BL76: Data Center's Provider Overview (Self-Built)
BL78: Top 10 provider based on their Data Center's inventory, facility size and energy consumption.
CF79: SUBREGION CODE | CG79: SUBREGION NAME | CH79: TOTAL DATA CENTERS | CI79: ISO/RTO ENERGY DEMAND | CJ79: DATA CENTER POWER CAPACITY | CK79: DATA CENTER ENERGY COVERAGE | CN79: SUBREGION CODE | CO79: SUBREGION NAME | CP79: TOTAL DATA CENTERS | CQ79: ISO/RTO ENERGY DEMAND | CR79: DATA CENTER POWER CAPACITY | CS79: DATA CENTER ENERGY COVERAGE
CF80: ='Data - ISO vs Data Centers'!A54 -> OPPD | CG80: ='Data - ISO vs Data Centers'!B54 -> Omaha Public Power District - SWPP | CH80: ='Data - ISO vs Data Centers'!C54 -> 24 | CI80: ='Data - ISO vs Data Centers'!D54 -> 2745.875 | CJ80: ='Data - ISO vs Data Centers'!E54 -> 905.9635 | CK80: ='Data - ISO vs Data Centers'!F54 -> 0.32993618 | CN80: ='Data - ISO vs Data Centers'!A66 -> 0035 | CO80: ='Data - ISO vs Data Centers'!B66 -> Zones 3 and 5 - MISO | CP80: ='Data - ISO vs Data Centers'!C66 -> 76 | CQ80: ='Data - ISO vs Data Centers'!D66 -> 13138.167 | CR80: ='Data - ISO vs Data Centers'!E66 -> 2433.9226 | CS80: ='Data - ISO vs Data Centers'!F66 -> 0.18525588
CF81: ='Data - ISO vs Data Centers'!A49 -> GRDA | CG81: ='Data - ISO vs Data Centers'!B49 -> Grand River Dam Authority - SWPP | CH81: ='Data - ISO vs Data Centers'!C49 -> 11 | CI81: ='Data - ISO vs Data Centers'!D49 -> 1443.25 | CJ81: ='Data - ISO vs Data Centers'!E49 -> 507.605 | CK81: ='Data - ISO vs Data Centers'!F49 -> 0.35170968 | CN81: ='Data - ISO vs Data Centers'!A65 -> 0027 | CO81: ='Data - ISO vs Data Centers'!B65 -> Zones 2 and 7 - MISO | CP81: ='Data - ISO vs Data Centers'!C65 -> 47 | CQ81: ='Data - ISO vs Data Centers'!D65 -> 21713.125 | CR81: ='Data - ISO vs Data Centers'!E65 -> 588.0715 | CS81: ='Data - ISO vs Data Centers'!F65 -> 0.027083688
CF82: ='Data - ISO vs Data Centers'!A57 -> WR | CG82: ='Data - ISO vs Data Centers'!B57 -> Westar Energy - SWPP | CH82: ='Data - ISO vs Data Centers'!C57 -> 8 | CI82: ='Data - ISO vs Data Centers'!D57 -> 5131.375 | CJ82: ='Data - ISO vs Data Centers'!E57 -> 38.3018 | CK82: ='Data - ISO vs Data Centers'!F57 -> 0.0074642372 | CN82: ='Data - ISO vs Data Centers'!A63 -> 0001 | CO82: ='Data - ISO vs Data Centers'!B63 -> Zone 1 - MISO | CP82: ='Data - ISO vs Data Centers'!C63 -> 32 | CQ82: ='Data - ISO vs Data Centers'!D63 -> 14687.75 | CR82: ='Data - ISO vs Data Centers'!E63 -> 332.6843 | CS82: ='Data - ISO vs Data Centers'!F63 -> 0.02265046
CF83: ='Data - ISO vs Data Centers'!A53 -> OKGE | CG83: ='Data - ISO vs Data Centers'!B53 -> Oklahoma Gas and Electric Co. - SWPP | CH83: ='Data - ISO vs Data Centers'!C53 -> 11 | CI83: ='Data - ISO vs Data Centers'!D53 -> 6403.5417 | CJ83: ='Data - ISO vs Data Centers'!E53 -> 33.16225 | CK83: ='Data - ISO vs Data Centers'!F53 -> 0.0051787357 | CN83: ='Data - ISO vs Data Centers'!A67 -> 8910 | CO83: ='Data - ISO vs Data Centers'!B67 -> Zones 8, 9 and 10 - MISO | CP83: ='Data - ISO vs Data Centers'!C67 -> 22 | CQ83: ='Data - ISO vs Data Centers'!D67 -> 27251.75 | CR83: ='Data - ISO vs Data Centers'!E67 -> 380.7997 | CS83: ='Data - ISO vs Data Centers'!F67 -> 0.013973404
CF84: ='Data - ISO vs Data Centers'!A50 -> INDN | CG84: ='Data - ISO vs Data Centers'!B50 -> Independence Power - SWPP | CH84: ='Data - ISO vs Data Centers'!C50 -> 8 | CI84: ='Data - ISO vs Data Centers'!D50 -> 172.04167 | CJ84: ='Data - ISO vs Data Centers'!E50 -> 62.64575 | CK84: ='Data - ISO vs Data Centers'!F50 -> 0.36413127 | CN84: ='Data - ISO vs Data Centers'!A64 -> 0006 | CO84: ='Data - ISO vs Data Centers'!B64 -> Zone 6 - MISO | CP84: ='Data - ISO vs Data Centers'!C64 -> 31 | CQ84: ='Data - ISO vs Data Centers'!D64 -> 11591.875 | CR84: ='Data - ISO vs Data Centers'!E64 -> 965.29605 | CS84: ='Data - ISO vs Data Centers'!F64 -> 0.083273504
CF85: ='Data - ISO vs Data Centers'!A56 -> SPS | CG85: ='Data - ISO vs Data Centers'!B56 -> Southwestern Public Service Company - SWPP | CH85: ='Data - ISO vs Data Centers'!C56 -> 2 | CI85: ='Data - ISO vs Data Centers'!D56 -> 5810.4167 | CJ85: ='Data - ISO vs Data Centers'!E56 -> 14.9579 | CK85: ='Data - ISO vs Data Centers'!F56 -> 0.0025743248 | CP85: =SUM(CP80:CP84) -> 208 | CQ85: =SUM(CQ80:CQ84) -> 88382.667 | CR85: =SUM(CR80:CR84) -> 4700.7741 | CS85: =CR85/CQ85 -> 0.053186607
CF86: ='Data - ISO vs Data Centers'!A55 -> SPRM | CG86: ='Data - ISO vs Data Centers'!B55 -> City of Springfield - SWPP | CH86: ='Data - ISO vs Data Centers'!C55 -> 1 | CI86: ='Data - ISO vs Data Centers'!D55 -> 573.91667 | CJ86: ='Data - ISO vs Data Centers'!E55 -> 6 | CK86: ='Data - ISO vs Data Centers'!F55 -> 0.010454479
CF87: ='Data - ISO vs Data Centers'!A52 -> MPS | CG87: ='Data - ISO vs Data Centers'!B52 -> KCP&L Greater Missouri Operations - SWPP | CH87: ='Data - ISO vs Data Centers'!C52 -> 2 | CI87: ='Data - ISO vs Data Centers'!D52 -> 1457.75 | CJ87: ='Data - ISO vs Data Centers'!E52 -> 4.4621 | CK87: ='Data - ISO vs Data Centers'!F52 -> 0.0030609501
CF88: ='Data - ISO vs Data Centers'!A51 -> LES | CG88: ='Data - ISO vs Data Centers'!B51 -> Lincoln Electric System - SWPP | CH88: ='Data - ISO vs Data Centers'!C51 -> 3 | CI88: ='Data - ISO vs Data Centers'!D51 -> 681.79167 | CJ88: ='Data - ISO vs Data Centers'!E51 -> 97 | CK88: ='Data - ISO vs Data Centers'!F51 -> 0.1422722
...

Sheet Data Sample
A1: ATERIO_DATA_CENTER_UID | B1: DATA_CENTER_BUILDING_NAME | C1: ATERIO_DATA_CENTER_CAMPUS_UID | D1: DATA_CENTER_CAMPUS_NAME | E1: DATA_CENTER_STAGE | F1: FLG_AI_FACILITY | G1: FLG_BTM_ONSITE_POWER_GENERATION | H1: TOT_PROJECT_COST | I1: ATERIO_PROVIDER_UID | J1: PROVIDER_NAME | K1: PROVIDER_URL | L1: PROVIDER_PUBLIC_PRIVATE | M1: PROVIDER_TICKER_NAME | N1: PROVIDER_BLOOMBERG_TICKER_NAME | O1: STOCK_EXCHANGE_PROVIDER_NAME | P1: PROVIDER_BACKED_BY | Q1: CONSTRUCTION_EQUIPMENT_PROVIDER_COMPANIES | R1: PROJECT_FINANCING_COMPANIES | S1: END_USER_COMPANIES | T1: FULL_ADDRESS | U1: ZIP_CODE | V1: COUNTY_FIPS_CODE | W1: COUNTY_NAME | X1: CITY_NAME | Y1: PLACE_FIPS_CODE | Z1: STATE_CODE | AA1: STATE_NAME | AB1: COUNTRY_CODE | AC1: COUNTRY_NAME | AD1: LOCATION_LATITUDE | AE1: LOCATION_LONGITUDE | AF1: SITE_ACREAGE | AG1: TOT_FACILITY_SPACE_SQFT | AH1: TOT_DATACENTER_SPACE_SQFT | AI1: PROV_PUB_TOT_POWER_CAPACITY_MW | AJ1: ATERIO_EST_TOT_POWER_CAPACITY_MW | AK1: ATERIO_EST_TOT_POWER_CAPACITY_MW_LOWER | AL1: ATERIO_EST_TOT_POWER_CAPACITY_MW_UPPER | AM1: SELECTED_POWER_CAPACITY_MW | AN1: CRITICAL_IT_CAPACITY_MW | AO1: YEARLY_PUE | AP1: TOT_NUM_GENERATORS | AQ1: DATA_CENTER_ANNOUNCED_DATE | AR1: DATA_CENTER_CANCELLED_DATE | AS1: DATA_CENTER_PROJECT_WITHDRAWN_DATE | AT1: DATA_CENTER_CONSTRUCTION_START_DATE | AU1: LATEST_SATELLITE_PICTURE_DATE | AV1: PCT_CONSTRUCTION_STATUS | AW1: DATA_CENTER_ACTIVATION_DATE | AX1: ESTIMATED_ACTIVATION_DATE_ATERIO | AY1: ESTIMATED_ACTIVATION_DATE_PUBLIC_SOURCE | AZ1: ESTIMATED_ACTIVATION_DATE_PUBLIC_SOURCE_URL | BA1: ATERIO_ELECTRICAL_UTILITY_UID | BB1: UTILITY_NAME | BC1: UTILITY_CODE | BD1: UTILITY_PUBLIC_PRIVATE | BE1: UTILITY_TICKER_NAME | BF1: UTILITY_BLOOMBERG_TICKER_NAME | BG1: UTILITY_EXCHANGE_PROVIDER_TICKER_NAME | BH1: ATERIO_BAL_AUTH_UID | BI1: BAL_AUTH_ABBR | BJ1: BAL_AUTH_NAME | BK1: ATERIO_BAL_AUTH_SUBREGION_UID | BL1: BAL_AUTH_SUBREGION_CODE | BM1: BAL_AUTH_SUBREGION_NAME | BN1: ATERIO_POWER_GENERATION_PROJECT_UID | BO1: DATASHEET_URL | BP1: MAP_URL | BQ1: PROJECT_PERMIT_URL | BR1: CAPEX_URL | BS1: PROJECT_EXECUTION_LIKELIHOOD | BT1: NOTES | BU1: RECORD_CREATED_DATE | BV1: RECORD_UPDATED_DATE | BW1: UPDATED_AT
A2: 14c3ec08-1803-4368-ac7a-fbd879e635eb | B2: Southfield Data Center NW (DC2) | C2: 15471167-b182-4a84-9204-3befe56d5657 | D2: Southfield, 123NET Campus | E2: Active | I2: f22930d7-d032-4fc9-90dd-ca83628f7994 | J2: 123NET | K2: https://www.123.net | L2: Private | P2: https://graingp.com/ | T2: 24275 Northwestern Hwy, Southfield, MI, USA | U2: 48075 | V2: 26125 | W2: Oakland County | X2: Southfield | Y2: 74900 | Z2: MI | AA2: Michigan | AB2: US | AC2: United States | AD2: 42.467033 | AE2: -83.235 | AG2: 21000 | AH2: 8000 | AI2: 1 | AJ2: 1.06 | AK2: 1.01 | AL2: 1.11 | AM2: 1 | AW2: 39020 | BA2: 26749c83-6e33-400d-b547-24f87a25d36b | BB2: DTE Electric Company | BC2: 5109 | BD2: Public | BE2: DTE | BF2: DTE:US | BG2: NYSE:DTE | BH2: cead66ff-8552-43d5-b723-aeedd7318b2b | BI2: MISO | BJ2: Midcontinent Independent System Operator | BK2: 3733cb81-030b-4603-b6fb-0888ceb4bd68 | BL2: 27 | BM2: Zones 2 and 7 - MISO | BO2: https://www.123.net/data-center-colocation/ | BP2: https://maps.app.goo.gl/5Qw1wJUiGjfo4GHP9 | BU2: 45474 | BV2: 46120 | BW2: 46238
A3: 302036dd-074a-45de-92fb-15bc3540a4c7 | B3: CHIL1 MTC Data Center | E3: Cancelled | I3: cc7c624a-756c-4183-8d7a-f4cc9f13aa97 | J3: 1547 Critical Systems Realty | K3: https://www.1547realty.com | L3: Private | T3: 40 E Garfield Blvd, Chicago, IL, USA | U3: 60615 | V3: 17031 | W3: Cook County | X3: Chicago | Y3: 14000 | Z3: IL | AA3: Illinois | AB3: US | AC3: United States | AD3: 41.794888 | AE3: -87.62457 | AG3: 230000 | AH3: 230000 | AI3: 24 | AJ3: 34.63 | AK3: 33.02 | AL3: 36.31 | AM3: 24 | AR3: 45303 | BA3: 222a249b-639d-4c33-9bba-36724efea762 | BB3: Commonwealth Edison Co | BC3: 4110 | BD3: Private (Part of Exelon Corp) | BE3: EXC | BF3: EXC:US | BG3: NASDAQ:EXC | BH3: 35f051b0-f1ce-470d-81d2-ea5c0d197f3a | BI3: PJM | BJ3: PJM Interconnection | BK3: e84646c2-7438-4a4c-916e-953518bd940a | BL3: CE | BM3: Commonwealth Edison zone - PJM | BO3: https://www.1547realty.com/data-center/chicago-il-chil1/ | BP3: https://maps.app.goo.gl/2KTnfi5z8T6e9XGi8 | BS3: Low | BT3: [2025-02-12 JR] Additional Info: Data Center sqft and capacity updated._x000D_ [2026-01-05 AV] Additional Info: Following the purchase of the building in 2015, no construction activity was observed in the area. In 2024, it was announced that the building would be put up for sale. Status updated to Cancelled. | BU3: 45474 | BV3: 46120 | BW3: 46238
A4: 28ab55b6-0148-4b98-87ad-c0b4d8dd2a05 | B4: ORNY1 Orangeburg Data Center | E4: Active | I4: cc7c624a-756c-4183-8d7a-f4cc9f13aa97 | J4: 1547 Critical Systems Realty | K4: https://www.1547realty.com | L4: Private | T4: 1 Ramland Road South, Orangeburg, NY, USA | U4: 10962 | V4: 36087 | W4: Rockland County | X4: Orangeburg | Y4: 55167 | Z4: NY | AA4: New York | AB4: US | AC4: United States | AD4: 41.03341 | AE4: -73.9708 | AG4: 232000 | AH4: 232000 | AI4: 24 | AJ4: 23.16 | AK4: 22.09 | AL4: 24.29 | AM4: 24 | AW4: 42034 | BA4: 85d629c4-28b0-47db-b275-107564a0a5d6 | BB4: Orange & Rockland Utils Inc | BC4: 14154 | BD4: Private | BH4: ee53ff3c-b180-48a0-b3fb-50539e5f46a0 | BI4: NYIS | BJ4: New York Independent System Operator | BO4: https://www.1547realty.com/data-center/orangeburg-new-york-orny1/ | BP4: https://maps.app.goo.gl/i1zLybhEV7R2aaTp6 | BT4: [2025-02-12 JR] Additional Info: Data Center sqft and capacity updated | BU4: 45474 | BV4: 46120 | BW4: 46238
A5: c5fe22bd-0670-427c-ae03-5674b8e007ef | B5: MIWI1 Wells Building Data Center | E5: Active | I5: cc7c624a-756c-4183-8d7a-f4cc9f13aa97 | J5: 1547 Critical Systems Realty | K5: https://www.1547realty.com | L5: Private | T5: 324 East Wisconsin Avenue, Milwaukee, WI, USA | U5: 53202 | V5: 55079 | W5: Milwaukee County | X5: Milwaukee | Y5: 53000 | Z5: WI | AA5: Wisconsin | AB5: US | AC5: United States | AD5: 43.03904 | AE5: -87.90704 | AG5: 160000 | AH5: 5000 | AI5: 0.5 | AJ5: 0.6 | AK5: 0.57 | AL5: 0.63 | AM5: 0.5 | AW5: 44077 | BA5: 94a63322-5c22-4deb-b119-22fd3e409638 | BB5: Wisconsin Electric Power Co | BC5: 20847 | BD5: Public | BE5: WEC | BF5: WEC:US | BG5: NYSE:WEC | BH5: cead66ff-8552-43d5-b723-aeedd7318b2b | BI5: MISO | BJ5: Midcontinent Independent System Operator | BK5: 3733cb81-030b-4603-b6fb-0888ceb4bd68 | BL5: 27 | BM5: Zones 2 and 7 - MISO | BO5: https://www.1547realty.com/data-center/milwaukee-wi-miwi1/ | BP5: https://maps.app.goo.gl/CYGECo5FQo559uWJA | BT5: [2026-01-09 AV] Additional Info: The facility was already functioning as a carrier‑hotel/data‑center before 2020, but 1547's footprint at the site began with its acquisition and branded deployment in 2020. | BU5: 45474 | BV5: 46120 | BW5: 46238
A6: 18ae0d0f-6185-486c-9d33-77c155f34105 | B6: CH6 Chicago Data Center | E6: Active | I6: 6c053c05-6487-42e6-9ad7-5c5b73168dbd | J6: 365 Data Centers | K6: https://www.365datacenters.com | L6: Private | T6: 427 South LaSalle Street, Chicago, IL, USA | U6: 60605 | V6: 17031 | W6: Cook County | X6: Chicago | Y6: 14000 | Z6: IL | AA6: Illinois | AB6: US | AC6: United States | AD6: 41.876213 | AE6: -87.631454 | AG6: 10000 | AH6: 10000 | AI6: 1 | AJ6: 1.51 | AK6: 1.44 | AL6: 1.58 | AM6: 1 | AW6: 36526 | BA6: 222a249b-639d-4c33-9bba-36724efea762 | BB6: Commonwealth Edison Co | BC6: 4110 | BD6: Private (Part of Exelon Corp) | BE6: EXC | BF6: EXC:US | BG6: NASDAQ:EXC | BH6: 35f051b0-f1ce-470d-81d2-ea5c0d197f3a | BI6: PJM | BJ6: PJM Interconnection | BK6: e84646c2-7438-4a4c-916e-953518bd940a | BL6: CE | BM6: Commonwealth Edison zone - PJM | BO6: https://365datacenters.com/chicago-data-center/ | BP6: https://maps.app.goo.gl/UreXPxboudebAeQZ8 | BU6: 45474 | BV6: 46120 | BW6: 46238
A7: af48ab77-f0ea-4c39-a5f2-d5f913a2ecee | B7: PA1 Philadelphia Data Center | E7: Active | I7: 6c053c05-6487-42e6-9ad7-5c5b73168dbd | J7: 365 Data Centers | K7: https://www.365datacenters.com | L7: Private | T7: 1500 Spring Garden Street, Philadelphia, PA, USA | U7: 19130 | V7: 42101 | W7: Philadelphia County | X7: Philadelphia | Y7: 60000 | Z7: PA | AA7: Pennsylvania | AB7: US | AC7: United States | AD7: 39.962116 | AE7: -75.164055 | AG7: 135100 | AH7: 135100 | AI7: 10 | AJ7: 9.55 | AK7: 9.11 | AL7: 10.01 | AM7: 10 | AW7: 39232 | BA7: 52a226db-b188-418c-89dc-e9ec5727be9c | BB7: PECO Energy Co | BC7: 14940 | BD7: Public | BE7: EXC | BF7: EXC:US | BG7: NASDAQ:EXC | BH7: 35f051b0-f1ce-470d-81d2-ea5c0d197f3a | BI7: PJM | BJ7: PJM Interconnection | BK7: ce983ef3-0d1d-4bd4-ae46-013f5f1d08b9 | BL7: PE | BM7: PECO Energy zone - PJM | BO7: https://365datacenters.com/philadelphia-data-center-2/ | BP7: https://maps.app.goo.gl/QvhwLVEkm1Da9j6P9 | BU7: 45474 | BV7: 46120 | BW7: 46238
A8: 691cc6a7-fd17-4148-89ab-776a6f40e273 | B8: TX1 Richardson Data Center | E8: Active | I8: 6c053c05-6487-42e6-9ad7-5c5b73168dbd | J8: 365 Data Centers | K8: https://www.365datacenters.com | L8: Private | T8: 1001 East Campbell Road, Richardson, TX, USA | U8: 75081 | V8: 48113 | W8: Dallas County | X8: Richardson | Y8: 61796 | Z8: TX | AA8: Texas | AB8: US | AC8: United States | AD8: 32.976135 | AE8: -96.70743 | AG8: 75100 | AH8: 75100 | AI8: 6 | AJ8: 6.54 | AK8: 6.24 | AL8: 6.86 | AM8: 6 | AW8: 37467 | BA8: 1ebbb343-179f-4d9d-a878-d6b03846b4c4 | BB8: City of Garland - (TX) | BC8: 6958 | BD8: Public (Municipality) | BH8: 1fc90153-5419-4455-91f9-cee1dda4ed00 | BI8: ERCO | BJ8: Electric Reliability Council of Texas | BK8: 14cc320b-3a3d-47a9-83a4-e27eff5c1700 | BL8: NCEN | BM8: ERCO - North Central | BO8: https://365datacenters.com/richardson-data-center/ | BP8: https://maps.app.goo.gl/t6xwpcRShHoH4iDj6 | BU8: 45474 | BV8: 46120 | BW8: 46238
A9: dc213783-9242-4152-a4bf-46764dfc5687 | B9: CMH01 Columbus OH Data Center Phase 1 | C9: 9cef7090-d546-11f0-a3aa-3b201b9c9e6f | D9: CMH Columbus OH Data Center Campus | E9: Construction | F9: Y | I9: 254c3d2c-a09a-4b4f-9cb3-2006286f77b3 | J9: 5C Data Centers | K9: https://www.5cdatacenters.com/ | L9: Private | Q9: FirstEnergy | T9: 601 Benjamin Dr, Springfield, OH 45502, USA | U9: 45502 | V9: 39023 | W9: Clark County | X9: Springfield | Y9: 74118 | Z9: OH | AA9: Ohio | AB9: US | AC9: United States | AD9: 39.912987 | AE9: -83.723946 | AF9: 40 | AG9: 320000 | AH9: 320000 | AI9: 100 | AJ9: 42.96 | AK9: 40.97 | AL9: 45.05 | AM9: 100 | AN9: 77 | AQ9: 45462 | AT9: 45658 | AU9: 46145 | AV9: 0.95 | AW9: 46295 | AX9: 46295 | BH9: 35f051b0-f1ce-470d-81d2-ea5c0d197f3a | BI9: PJM | BJ9: PJM Interconnection | BK9: 48653d43-e0c7-46dd-baf2-6b598abf970d | BL9: ATSI | BM9: American Transmission Systems, Inc. zone - PJM | BO9: https://5c.ai/datacenters | BP9: https://maps.app.goo.gl/2gTERUfS4fVEqanM7 | BQ9: https://www.firstenergycorp.com/content/dam/corporate/transmission/Ohio/e-springfield-n-titus-cn.pdf | BS9: High | BT9: [2024-12-19 JR] Latest Satellite: 2024-10-29; Construction Status: Site Preparation; Estimated Active Date By: Aterio; Additional Info: 200MW of power capacity is secured and set for delivery to the site, with the first 100MW scheduled for Q1 2025_x000D_ [2025-12-09 FC] Construction: Roof installation is largely complete with active mechanical and exterior site work visible; generator installation largely completed._x000D_ [2026-03-11 SQ] Construction: Generator installation appears to be complete in the expansion site, there is some minor equipment installation on the original building and the structural connection between both buildings is also complete. Additional Info: 5C aquired a former data center and is planning to renovate it and construct an expansion to reach 200 MW. Activation date updated from 2026-05-30 to the end of Q2 2026. _x000D_ [2026-07-02 DS] Additional Info: Waiting for a new satellite image to confirm activation status._x000D_ [2026-07-07 JR] Construction: All equipment in place, heavy machinery visible on site still; Additional Info: Activation date updated from 2026-07-07 to Q3 2026._x000D_ [2026-07-08 JR] Additional Info: Sales team claimed "yes CMH01 is operational", likely partial activation full ramp-up possible for early Q3 based on construction progress. | BU9: 45614 | BV9: 46211 | BW9: 46238
A10: 5f8b34d4-0ae0-40c3-b9c0-03ad25db79c9 | B10: Perseus Phase I | C10: dee6bd70-dd19-11f0-8ff6-b30471a54151 | D10: Perseus Campus | E10: Announcement | F10: Y | H10: 800000000 | I10: 7014049a-e25f-4eb0-97c4-f4c7ec283b3b | J10: AVAIO Digital | K10: https://avaiodigital.com/ | L10: Private | Q10: PG&E | T10: 2232 Golf Club Rd, Pittsburg, CA, USA | U10: 94565 | V10: 6013 | W10: Contra Costa County | X10: Pittsburg | Y10: 57456 | Z10: CA | AA10: California | AB10: US | AC10: United States | AD10: 38.012894 | AE10: -121.90964 | AF10: 101 | AG10: 745771 | AH10: 745771 | AI10: 99 | AJ10: 67.42 | AK10: 64.29 | AL10: 70.7 | AM10: 99 | AQ10: 45638 | AU10: 46217 | AV10: 0 | AW10: 46568 | AX10: 47026 | AY10: 46568 | AZ10: https://www.avaiodigital.com/updates/avaio-digital-partners-achieves-major-milestone-for-pittsburg-technology-park-perseus-data-center-project | BA10: 625b7686-055b-46e1-a5a4-4e3dcaf631b4 | BB10: Pacific Gas & Electric Co. | BC10: 14328 | BD10: Public | BE10: PCG | BF10: PCG:US | BG10: NYSE:PCG | BH10: 2950a9eb-39ef-4949-96bd-ecefbf7db624 | BI10: CISO | BJ10: California Independent System Operator | BK10: 9bbe5250-047e-4a37-8434-4cda4fceb9e5 | BL10: PGAE | BM10: Pacific Gas and Electric | BO10: https://avaiodigital.com/avaio-digital-partners-achieves-major-milestone-for-pittsburg-technology-park-perseus-data-center-project/, https://www.prnewswire.com/news-releases/avaio-digital-marks-major-milestone-as-cec-approves-99mw-for-bay-area-data-center-project-perseus-302636094.html, https://www.pittsburgca.gov/home/showpublisheddocument/16451/638555442556300000 | BP10: https://maps.app.goo.gl/2rH1ADUVNz9V8iAE7 | BS10: High | BT10: [2025-12-19 FC] Additional Info: Updated co-ordinates, data sheet URL with proposed phased site plan, square footage from 347,740 and added to campus; project could scale up to 500MW delivered in multiple 99MW phases with phase 1 to be delivered by 2027 | BU10: 45643 | BV10: 46230 | BW10: 46238
A11: d60c1367-3801-4cf5-b4ba-992714428f47 | B11: NEO-01 Perkins Township Data Center | E11: Construction | I11: 3d55dfe8-9ebe-42f7-b66f-1d6fc81bf469 | J11: Aligned Data Centers | K11: https://www.aligneddc.com | L11: Private | P11: AI Infrastructure Partnership (AIP), MGX, and BlackRock’s Global Infrastructure Partners (GIP) | T11: 2509 Hayes Ave, Sandusky, OH | U11: 44870 | V11: 39043 | W11: Erie County | X11: Sandusky | Y11: 70380 | Z11: OH | AA11: Ohio | AB11: US | AC11: United States | AD11: 41.43104 | AE11: -82.71716 | AF11: 128 | AG11: 200000 | AH11: 200000 | AI11: 96 | AJ11: 32.5 | AK11: 30.99 | AL11: 34.08 | AM11: 96 | AN11: 72 | AP11: 42 | AT11: 45566 | AU11: 46156 | AV11: 0.9 | AW11: 46295 | AX11: 46295 | BA11: 6c6655b1-8b8e-45b1-bd02-146ed6379690 | BB11: Ohio Edison Co | BC11: 13998 | BD11: Public | BE11: FE | BF11: FE:US | BG11: NYSE:FE | BH11: 35f051b0-f1ce-470d-81d2-ea5c0d197f3a | BI11: PJM | BJ11: PJM Interconnection | BK11: 48653d43-e0c7-46dd-baf2-6b598abf970d | BL11: ATSI | BM11: American Transmission Systems, Inc. zone - PJM | BO11: https://aligneddc.com/ohio/ | BP11: https://maps.app.goo.gl/xHJQhwAU3VvfySt68 | BS11: High | BT11: [2024-12-19 JR] Latest Satellite: 2024-10-18; Construction Status: Site Preparation; Estimated Active Date By: Aterio_x000D_ [2025-08-01 JR] Construction: Shell complete with significant rooftop installations; generator and cooling equipment placement in progress._x000D_ [2025-10-06 DP] Construction: Roof nearly complete; cooling units being installed on west and north sections. Cranes active and surrounding groundwork ongoing._x000D_ [2026-02-02 JR] Construction: Building shell and roof are complete. Generators are partially installed along the perimeter, with multiple units still missing. Cranes remain on-site and active construction is visible, indicating ongoing equipment installation and the project is not yet fully commissioned; Additional Info: Activation date updated from 2026-01-30 to Q2 2026. Possible partial activation, but not full activation as of January 2026._x000D_ [2026-03-16 SQ] Additional Info: Satellite Image pending to confirm construction progress. _x000D_ [2026-05-19 SQ] Construction: The structure and roof of the data center building appear to be complete, with a large array of cooling equipment and generators installed throughout the facility; paving of the grounds is underway, and there is activity in the parking lot, suggesting that partial testing is being conducted in accordance with progress; Additional Info: Activation Date updated from 2026-06-30 to Q3 2026 | BU11: 45600 | BV11: 46202 | BW11: 46238
A12: 1caf3f25-38c7-4d1e-9e29-ac5fc05860d3 | B12: IAD04- Building 1 | C12: ec110aa8-6db5-4a1d-ab69-802992378f4b | D12: Aligned Frederick Campus | E12: Construction | F12: Y | I12: 3d55dfe8-9ebe-42f7-b66f-1d6fc81bf469 | J12: Aligned Data Centers | K12: https://www.aligneddc.com | L12: Private | P12: AI Infrastructure Partnership (AIP), MGX, and BlackRock’s Global Infrastructure Partners (GIP) | Q12: Turner Construction Company | T12: 5601 Manor Woods Road, Frederick, MD | U12: 21703 | V12: 24021 | W12: Frederick County | X12: Frederick | Y12: 30325 | Z12: MD | AA12: Maryland | AB12: US | AC12: United States | AD12: 39.33426 | AE12: -77.47308 | AF12: 75 | AG12: 450000 | AH12: 450000 | AI12: 72 | AJ12: 61.69 | AK12: 58.83 | AL12: 64.69 | AM12: 72 | AN12: 72 | AP12: 42 | AQ12: 45057 | AT12: 45672 | AU12: 46207 | AV12: 0.85 | AW12: 46325 | AX12: 46325 | BA12: cb3fad47-2ad9-4619-95a4-2e146884f783 | BB12: First Electric Coop Corp | BC12: 6342 | BH12: 35f051b0-f1ce-470d-81d2-ea5c0d197f3a | BI12: PJM | BJ12: PJM Interconnection | BK12: 4bb6bca9-55a9-4621-a4c2-dc6c51f58c5e | BL12: AP | BM12: Allegheny Power zone - PJM | BO12: https://aligneddc.com/maryland/, https://mde.maryland.gov/programs/permits/AirManagementPermits/Documents/Public-Review/Alt%20NSPS/AlignedDataCentersAirPermittoConstructApplication.pdf, https://www.datacenterknowledge.com/data-center-site-selection/why-frederick-county-is-important-for-the-nova-data-center-market | BP12: https://maps.app.goo.gl/nNqw33F93EkvcKgy9 | BQ12: https://mde.maryland.gov/programs/permits/AirManagementPermits/Documents/Public-Review/Alt%20NSPS/AlignedDataCentersAirPermittoConstructApplication.pdf, https://www.frederickcountymd.gov/ArchiveCenter/ViewFile/Item/15820 | BS12: High | BT12: [2024-12-19 JR] Latest Satellite: 2024-08-11; Construction Status: No Construction; Estimated Active Date By: Aterio_x000D_ [2024-12-19 JR] Additional Info: Stage Updated to Construction_x000D_ [2025-08-06 JR] Construction: Foundation completed; vertical construction underway._x000D_ [2025-10-09 DP] Construction: Building shell and roof partially completed, with cranes active and ongoing structural assembly. Foundation work and equipment placement visible on surrounding areas, indicating mid-stage development._x000D_ [2026-03-12 DS] Construction: Work underway on the equipment yard. Cooling vents being installed on the roof; Additional Info: Updated number of buildings in the campus from 7 to 4._x000D_ [2026-07-07 SQ] Construction: Vertical construction is now fully complete. The cooling towers have been fully installed, and the installation of the generators is nearing completion. Work on the building's exterior is currently ongoing. | BU12: 45614 | BV12: 46210 | BW12: 46238
A13: 83c7ee62-afb5-4d5f-bedf-b25ca38184fc | B13: AWS Central Expy Data Center | E13: Land Bank | I13: 00a5efa3-8d76-4878-a0d6-f90a60f8b647 | J13: Amazon AWS | K13: https://www.aws.amazon.com/compliance/data-center/data-centers/ | L13: Public | M13: AMZN | N13: AMZN:US | O13: NASDAQ: AMZN | T13: 960 Central Expy, Santa Clara, CA, USA | U13: 95050 | V13: 6085 | W13: Santa Clara County | X13: Santa Clara | Y13: 69084 | Z13: CA | AA13: California | AB13: US | AC13: United States | AD13: 37.372887 | AE13: -121.95424 | AJ13: 39.81 | AK13: 38.76 | AL13: 40.88 | AM13: 39.81 | AU13: 46149 | AV13: 0 | AW13: 46568 | BA13: 625b7686-055b-46e1-a5a4-4e3dcaf631b4 | BB13: Pacific Gas & Electric Co. | BC13: 14328 | BD13: Public | BE13: PCG | BF13: PCG:US | BG13: NYSE:PCG | BH13: 2950a9eb-39ef-4949-96bd-ecefbf7db624 | BI13: CISO | BJ13: California Independent System Operator | BK13: 9bbe5250-047e-4a37-8434-4cda4fceb9e5 | BL13: PGAE | BM13: Pacific Gas and Electric | BO13: https://www.mercurynews.com/2023/03/07/amazon-santa-clara-buy-sell-real-estate-owens-corning-build-tech/ | BP13: https://maps.app.goo.gl/sE1L4CiHG9G2ZRxX9 | BS13: Medium | BT13: [2025-12-19 FC] Additional Info: Updated status from Announcement | BU13: 45616 | BV13: 46219 | BW13: 46238
A14: 3542a6db-986b-4d40-93ac-862194e99e28 | B14: AWS Ezell Drive Data Center | E14: Announcement | I14: 00a5efa3-8d76-4878-a0d6-f90a60f8b647 | J14: Amazon AWS | K14: https://www.aws.amazon.com/compliance/data-center/data-centers/ | L14: Public | M14: AMZN | N14: AMZN:US | O14: NASDAQ: AMZN | T14: 1800-1898 Jo Dr, DeSoto, TX, USA | U14: 75115 | V14: 48113 | W14: Dallas County | X14: Desoto | Z14: TX | AA14: Texas | AB14: US | AC14: United States | AD14: 32.62468 | AE14: -96.86052 | AF14: 9 | AG14: 30000 | AH14: 30000 | AJ14: 7.1 | AK14: 6.91 | AL14: 7.29 | AM14: 7.1 | AQ14: 44819 | AU14: 46212 | AV14: 0 | AW14: 46629 | AY14: 45657 | BA14: 14246342-1edf-4a4e-825c-0bf93f13d201 | BB14: Oncor Electric Delivery Company LLC | BC14: 44372 | BH14: 1fc90153-5419-4455-91f9-cee1dda4ed00 | BI14: ERCO | BJ14: Electric Reliability Council of Texas | BK14: 14cc320b-3a3d-47a9-83a4-e27eff5c1700 | BL14: NCEN | BM14: ERCO - North Central | BO14: https://www.dallasnews.com/business/real-estate/2022/09/13/amazon-plans-new-data-center-in-southern-dallas-county/ | BP14: https://maps.app.goo.gl/VusXq4hV7wzgJJME9 | BQ14: https://www.tdlr.texas.gov/TABS/Search/Project/TABS2023000811 | BS14: Low | BT14: [2024-12-19 JR] Latest Satellite: 2023-11-13; Construction Status: No Construction; Estimated Active Date By: Aterio; Additional Info: Project Delayed_x000D_ [2025-05-27 JR] Construction: No construction activity as of latest satellite imagery. _x000D_ [2025-11-12 JR] Construction: No construction visible; Additional Info: Activation date updated from 2026-08-30_x000D_ [2026-04-08 JH] Construction: No visible construction activity observed on site. | BU14: 45637 | BV14: 46220 | BW14: 46238
A15: ecdeba1b-9e90-42a4-85c1-d34aff607d26 | B15: Amazon AWS IAD - 11200 Thomasson | E15: Active | I15: 00a5efa3-8d76-4878-a0d6-f90a60f8b647 | J15: Amazon AWS | K15: https://www.aws.amazon.com/compliance/data-center/data-centers/ | L15: Public | M15: AMZN | N15: AMZN:US | O15: NASDAQ: AMZN | T15: 11200 Thomasson Barn Road, Manassas, VA, USA | U15: 20109 | V15: 51153 | W15: Prince William County | X15: Manassas | Y15: 48952 | Z15: VA | AA15: Virginia | AB15: US | AC15: United States | AD15: 38.743847 | AE15: -77.53042 | AG15: 149404 | AH15: 149404 | AJ15: 35 | AK15: 34.08 | AL15: 35.94 | AM15: 35 | AN15: 30.43 | AO15: 1.15 | AP15: 16 | AW15: 43905 | BA15: 1f3c7b79-c506-4062-b210-2af9580f0d84 | BB15: City of Manassas - (VA) | BC15: 11560 | BD15: Private | BH15: 35f051b0-f1ce-470d-81d2-ea5c0d197f3a | BI15: PJM | BJ15: PJM Interconnection | BK15: 469a7dc0-fc5e-4f8e-8184-301f28134241 | BL15: DOM | BM15: Dominion Virginia Power zone - PJM | BP15: https://maps.app.goo.gl/6Q26m7kXGpTAEmbq6 | BT15: [2025-02-11JR] Additional Info: Owned by COPT _x000D_ [2025-02-28 JR] Additional Info: PUE is the average for Operational Global Data Center as of 2023_x000D_ [2025-04-29 JR] Additional Info: Selected power capacity updated based on number of generators observed in satellite imagery. | BU15: 45474 | BV15: 46219 | BW15: 46238
A16: 77ac6a16-efd6-49b8-bbfc-7a1e32626833 | B16: Amazon AWS IAD - 44150 Wade Dr | E16: Announcement | I16: 00a5efa3-8d76-4878-a0d6-f90a60f8b647 | J16: Amazon AWS | K16: https://www.aws.amazon.com/compliance/data-center/data-centers/ | L16: Public | M16: AMZN | N16: AMZN:US | O16: NASDAQ: AMZN | T16: 44150 Wade Dr, Chantilly, VA 20152, USA | U16: 20152 | V16: 51107 | W16: Loudoun County | X16: Chantilly | Y16: 14744 | Z16: VA | AA16: Virginia | AB16: US | AC16: United States | AD16: 38.920685 | AE16: -77.47298 | AF16: 24 | AG16: 350000 | AH16: 423575 | AJ16: 56.28 | AK16: 54.81 | AL16: 57.8 | AM16: 56.28 | AP16: 20 | AQ16: 45117 | AU16: 46193 | AV16: 0 | AW16: 46447 | AX16: 46447 | BA16: 498190ca-b66d-4a6a-becc-3657df8fca8d | BB16: Northern Virginia Elec Coop | BC16: 13640 | BD16: Private | BH16: 35f051b0-f1ce-470d-81d2-ea5c0d197f3a | BI16: PJM | BJ16: PJM Interconnection | BK16: 469a7dc0-fc5e-4f8e-8184-301f28134241 | BL16: DOM | BM16: Dominion Virginia Power zone - PJM | BO16: https://www.bisnow.com/washington-dc/news/deal-sheet/this-weeks-dc-deal-sheet-119715 | BP16: https://maps.app.goo.gl/dMX9UvX9i1crkizw8 | BQ16: https://loudouncountyvaeg.tylerhost.net/prod/selfservice#/plan/9bc502fd-3d1b-49b4-a765-b3da727ac11f?tab=attachments,https://loudoun.granicus.com/MetaViewer.php?view_id=78&event_id=3451&meta_id=221074#page=11&zoom=100,93,113 | BS16: High | BT16: [2024-12-19 JR] Latest Satellite: 2024-04-16; Construction Status: No Construction; Estimated Active Date By: Aterio; Additional Info: Land bought from Firefox_x000D_ [2025-04-29 JR] Construction: No vertical construction observed. Site appears cleared and partially graded. No active building activity at this stage._x000D_ [2025-12-30 AV] Additional Info: Activation date updated from 2026-09-30. No visible signs of construction. _x000D_ [2026-04-08 JH] Construction: No visible construction activity observed on site. | BU16: 45474 | BV16: 46219 | BW16: 46238
A17: 06bd1449-2708-4d9c-87f4-bef5f684c439 | B17: AWS NCTC Building 1 | C17: c3cef5b5-f06e-47d6-9e0c-a2fc2457d133 | D17: AWS Northeast Creek Tech Campus | E17: Construction | I17: 00a5efa3-8d76-4878-a0d6-f90a60f8b647 | J17: Amazon AWS | K17: https://www.aws.amazon.com/compliance/data-center/data-centers/ | L17: Public | M17: AMZN | N17: AMZN:US | O17: NASDAQ: AMZN | T17: X2MX+P5 Mineral, VA, USA | U17: 23117 | V17: 51109 | W17: Louisa County | X17: Mineral | Y17: 52120 | Z17: VA | AA17: Virginia | AB17: US | AC17: United States | AD17: 37.984306 | AE17: -77.95212 | AF17: 374 | AG17: 382000 | AH17: 382000 | AI17: 70 | AJ17: 39.2 | AK17: 38.17 | AL17: 40.25 | AM17: 70 | AQ17: 45600 | AT17: 45864 | AU17: 46186 | AV17: 0.15 | AW17: 46751 | AX17: 46751 | BA17: 6f92e568-ff47-4893-8e13-f98d40e662a4 | BB17: Rappahannock Electric Coop | BC17: 40228 | BD17: Private (Cooperative) | BH17: 35f051b0-f1ce-470d-81d2-ea5c0d197f3a | BI17: PJM | BJ17: PJM Interconnection | BK17: 469a7dc0-fc5e-4f8e-8184-301f28134241 | BL17: DOM | BM17: Dominion Virginia Power zone - PJM | BO17: https://www.nao.usace.army.mil/Media/Public-Notices/Article/3952905/nao-2024-01939-amazon-data-services-louisa-virginia/ | BP17: https://maps.app.goo.gl/MoCkLG935b63MWoe7 | BQ17: https://www.nao.usace.army.mil/Media/Public-Notices/Article/3952905/nao-2024-01939-amazon-data-services-louisa-virginia/ | BS17: High | BT17: [2024-03-12 JR] Latest Satellite: 2025-03-03; Construction Status: No Construction; Estimated Active Date By: AWS_x000D_ [2024-12-19 JR] Latest Satellite: 2021-10-21; Construction Status: No Construction; Estimated Active Date By: AWS_x000D_ [2025-09-07 DP] Construction: Significant land clearing and grading activity visible_x000D_ [2025-12-02 DP] Construction: Foundation work underway_x000D_ [2026-03-24 SQ] Construction: No significant progress to update percentage; Additional Info: Activation Date update from 2026-06-30 to Q4 2027._x000D_ [2026-05-28 AV] Construction: No significant progress to update percentage. _x000D_ [2026-06-25 SQ] Construction: No significant progress to update percentage. | BU17: 45636 | BV17: 46219 | BW17: 46238
A18: 21356727-827e-4d88-8a15-772459ff323c | B18: AWS Summit Crossing Building 1 | C18: ae37b109-2a22-4363-94f3-e00fae92adb8 | D18: AWS Summit Crossing Tech Campus | E18: Announcement | I18: 00a5efa3-8d76-4878-a0d6-f90a60f8b647 | J18: Amazon AWS | K18: https://www.aws.amazon.com/compliance/data-center/data-centers/ | L18: Public | M18: AMZN | N18: AMZN:US | O18: NASDAQ: AMZN | T18: 5HW9+VC Olive, VA, USA | U18: 22408 | V18: 51177 | W18: Spotsylvania County | X18: Fredericksburg | Y18: 29744 | Z18: VA | AA18: Virginia | AB18: US | AC18: United States | AD18: 38.197132 | AE18: -77.43137 | AF18: 231 | AG18: 300000 | AH18: 300000 | AJ18: 66 | AK18: 64.97 | AL18: 67.06 | AM18: 66 | AQ18: 45214 | AU18: 46206 | AV18: 0 | AW18: 47026 | AX18: 47026 | BA18: 5b0c2f7d-42e6-4e89-997c-39d2e368e019 | BB18: Virginia Electric & Power Co | BC18: 19876 | BD18: Public | BE18: D | BF18: D:US | BG18: NYSE:D | BH18: 35f051b0-f1ce-470d-81d2-ea5c0d197f3a | BI18: PJM | BJ18: PJM Interconnection | BK18: 469a7dc0-fc5e-4f8e-8184-301f28134241 | BL18: DOM | BM18: Dominion Virginia Power zone - PJM | BO18: https://fredericksburg.com/news/local/data-center-proposals-pile-up-in-spotsylvania/article_0b3a873c-ff26-11ed-97a1-df0bb17d1b49.html | BP18: https://maps.app.goo.gl/petKvnEPAhsxdXSu5 | BQ18: https://www.spotsylvania.va.us/DocumentCenter/View/33280/2nd-Submission-Narrative-?bidId= | BS18: Medium | BT18: [2025-04-01 JR] Additional Info: Correction made on Activation date and Stage based on new satellite image_x000D_ [2025-12-22 JR] Additional Info: Estimated Power Capacity Added._x000D_ [2025-12-30 AV] Additional Info: Activation date updated from 2026-08-30. No visible signs of construction._x000D_ [2026-04-16 JR] Additional Info: No construction visible; Activation date updated from 2027-03-31 to Q3 2028. | BU18: 45637 | BV18: 46219 | BW18: 46238
A19: e0996f61-ef80-43e2-a3ae-330e1da689ae | B19: Amazon AWS - Houchard Building 3 | C19: 7096adec-37f7-4126-9eb9-7376f4220ebe | D19: Dublin 1, AWS Campus | E19: Active | I19: 00a5efa3-8d76-4878-a0d6-f90a60f8b647 | J19: Amazon AWS | K19: https://www.aws.amazon.com/compliance/data-center/data-centers/ | L19: Public | M19: AMZN | N19: AMZN:US | O19: NASDAQ: AMZN | T19: 6830 Crosby Ct, Plain City, OH, USA | U19: 43064 | V19: 39159 | W19: Union County | X19: Plain City | Y19: 63030 | Z19: OH | AA19: Ohio | AB19: US | AC19: United States | AD19: 40.101833 | AE19: -83.19948 | AF19: 85 | AG19: 150500 | AH19: 150500 | AJ19: 22.5 | AK19: 21.91 | AL19: 23.11 | AM19: 22.5 | AN19: 19.57 | AO19: 1.15 | AP19: 11 | AW19: 44407 | BA19: 030eb1d3-5a7a-41c1-adf2-ff1890871e2f | BB19: Ohio Power Co | BC19: 14006 | BD19: Public | BE19: AEP | BF19: AEP:US | BG19: NASDAQ:AEP | BH19: 35f051b0-f1ce-470d-81d2-ea5c0d197f3a | BI19: PJM | BJ19: PJM Interconnection | BK19: f8f462a4-1283-4082-a7eb-2a242f708d96 | BL19: DAY | BM19: Dayton Power null zone - PJM | BO19: https://www.econdev.dublinohiousa.gov/2020/wp-content/uploads/2016/01/Crosby-Court-Job-Ready-Site-Dublin-Ohio-USA.pdf | BP19: https://maps.app.goo.gl/Ftb2AnGSFkRayDNy9 | BT19: [2024-12-19 JR] Additional Info: Area Estimated by Aterio_x000D_ [2025-02-28 JR] Additional Info: PUE is the average for Operational Global Data Center as of 2023_x000D_ [2025-04-29 JR] Additional Info: Selected power capacity updated based on number of generators observed in satellite imagery. | BU19: 45621 | BV19: 46219 | BW19: 46238
